[3f7d61a3-d57b-462c-aed4-0ce03cad12a9] Webhook connection error for reference_id=TEST-b07bd4cf-f211-4d33-a174-3ae5d6b55412: HTTPConnectionPool(host='localhost', port=8001): Max retries exceeded with url: /webhook (Caused by NewConnectionError('<urllib3.connection.HTTPConnection object at 0x1066d30e0>: Failed to establish a new connection: [Errno 61] Connection refused'))
[fa78ed59-9c2e-4302-8f8c-18321cc1de00] Webhook connection error for reference_id=SP826561222312211_EBI-B8231735EED347D: HTTPConnectionPool(host='localhost', port=9001): Max retries exceeded with url: /webhook-receiver (Caused by NewConnectionError('<urllib3.connection.HTTPConnection object at 0x1066d34d0>: Failed to establish a new connection: [Errno 61] Connection refused'))
[e39de707-f18d-417d-becc-a676ae612d1f] Webhook connection error for reference_id=SP826561222312211_EBI-B8231735EED347D: HTTPConnectionPool(host='localhost', port=9001): Max retries exceeded with url: /webhook-receiver (Caused by NewConnectionError('<urllib3.connection.HTTPConnection object at 0x1066d2cf0>: Failed to establish a new connection: [Errno 61] Connection refused'))
[4243388e-ecbe-4bec-831d-703bee53e22a] Webhook connection error for reference_id=SP826561222312211_EBI-B8231735EED347D: HTTPConnectionPool(host='localhost', port=9001): Max retries exceeded with url: /webhook-receiver (Caused by NewConnectionError('<urllib3.connection.HTTPConnection object at 0x1067360d0>: Failed to establish a new connection: [Errno 61] Connection refused'))
[4243388e-ecbe-4bec-831d-703bee53e22a] Webhook delivery failed for reference_id=SP826561222312211_EBI-B8231735EED347D: Status 500, Response: {"message": "Internal error!!"}
[4243388e-ecbe-4bec-831d-703bee53e22a] Error sending webhook for reference_id=SP826561222312211_EBI-B8231735EED347D: Webhook failed with status 500: {"message": "Internal error!!"}
[e39de707-f18d-417d-becc-a676ae612d1f] Webhook connection error for reference_id=SP826561222312211_EBI-B8231735EED347D: HTTPConnectionPool(host='localhost', port=9001): Max retries exceeded with url: /webhook-receiver (Caused by NewConnectionError('<urllib3.connection.HTTPConnection object at 0x106736350>: Failed to establish a new connection: [Errno 61] Connection refused'))
[3f7d61a3-d57b-462c-aed4-0ce03cad12a9] Webhook connection error for reference_id=TEST-b07bd4cf-f211-4d33-a174-3ae5d6b55412: HTTPConnectionPool(host='localhost', port=8001): Max retries exceeded with url: /webhook (Caused by NewConnectionError('<urllib3.connection.HTTPConnection object at 0x106726650>: Failed to establish a new connection: [Errno 61] Connection refused'))
[fa78ed59-9c2e-4302-8f8c-18321cc1de00] Webhook connection error for reference_id=SP826561222312211_EBI-B8231735EED347D: HTTPConnectionPool(host='localhost', port=9001): Max retries exceeded with url: /webhook-receiver (Caused by NewConnectionError('<urllib3.connection.HTTPConnection object at 0x106726b10>: Failed to establish a new connection: [Errno 61] Connection refused'))
[cc07044c-53f1-4547-99f3-f9dfe2fbdb07] Webhook connection error for reference_id=SP826561222312211_EBI-B8231735EED347D: HTTPConnectionPool(host='localhost', port=9001): Max retries exceeded with url: /webhook-receiver (Caused by NewConnectionError('<urllib3.connection.HTTPConnection object at 0x106706b10>: Failed to establish a new connection: [Errno 61] Connection refused'))
[cc07044c-53f1-4547-99f3-f9dfe2fbdb07] Webhook connection error for reference_id=SP826561222312211_EBI-B8231735EED347D: HTTPConnectionPool(host='localhost', port=9001): Max retries exceeded with url: /webhook-receiver (Caused by NewConnectionError('<urllib3.connection.HTTPConnection object at 0x106736c10>: Failed to establish a new connection: [Errno 61] Connection refused'))
[190f1d9a-962e-4d37-bc40-00d729be1ed6] Webhook connection error for reference_id=SP826561222312211_EBI-B8231735EED347D: HTTPConnectionPool(host='localhost', port=9001): Max retries exceeded with url: /webhook-receiver (Caused by NewConnectionError('<urllib3.connection.HTTPConnection object at 0x1066f1260>: Failed to establish a new connection: [Errno 61] Connection refused'))
[190f1d9a-962e-4d37-bc40-00d729be1ed6] Webhook connection error for reference_id=SP826561222312211_EBI-B8231735EED347D: HTTPConnectionPool(host='localhost', port=9001): Max retries exceeded with url: /webhook-receiver (Caused by NewConnectionError('<urllib3.connection.HTTPConnection object at 0x106722c40>: Failed to establish a new connection: [Errno 61] Connection refused'))
[bc6adca1-848d-412e-8396-7ce8e7bf4bba] Webhook connection error for reference_id=SP826561222312211_EBI-B8231735EED347D: HTTPConnectionPool(host='localhost', port=9001): Max retries exceeded with url: /webhook-receiver (Caused by NewConnectionError('<urllib3.connection.HTTPConnection object at 0x1066f2f10>: Failed to establish a new connection: [Errno 61] Connection refused'))
[bc6adca1-848d-412e-8396-7ce8e7bf4bba] Webhook connection error for reference_id=SP826561222312211_EBI-B8231735EED347D: HTTPConnectionPool(host='localhost', port=9001): Max retries exceeded with url: /webhook-receiver (Caused by NewConnectionError('<urllib3.connection.HTTPConnection object at 0x106721f30>: Failed to establish a new connection: [Errno 61] Connection refused'))
[6b4318bf-3e4d-4167-ac3f-fbeb98012eb3] Error sending webhook for reference_id=test-2025-08-08T16:19:40.498071+00:00: 500 Server Error: Internal Server Error for url: http://localhost:9001/webhook-receiver
[6b4318bf-3e4d-4167-ac3f-fbeb98012eb3] Stack trace: Traceback (most recent call last):
  File "/Users/cto/Desktop/projects/yolo/api.py", line 852, in send_webhook_notification
    raise e
  File "/Users/cto/Desktop/projects/yolo/api.py", line 843, in send_webhook_notification
    response.raise_for_status()  # Raise exception for 5XX status codes
    ~~~~~~~~~~~~~~~~~~~~~~~~~^^
  File "/Users/cto/myvenv/lib/python3.13/site-packages/requests/models.py", line 1024, in raise_for_status
    raise HTTPError(http_error_msg, response=self)
requests.exceptions.HTTPError: 500 Server Error: Internal Server Error for url: http://localhost:9001/webhook-receiver

[6b4318bf-3e4d-4167-ac3f-fbeb98012eb3] Error sending webhook for reference_id=test-2025-08-08T16:19:40.498071+00:00: 500 Server Error: Internal Server Error for url: http://localhost:9001/webhook-receiver
[6b4318bf-3e4d-4167-ac3f-fbeb98012eb3] Stack trace: Traceback (most recent call last):
  File "/Users/cto/Desktop/projects/yolo/api.py", line 852, in send_webhook_notification
    raise e
  File "/Users/cto/Desktop/projects/yolo/api.py", line 843, in send_webhook_notification
    response.raise_for_status()  # Raise exception for 5XX status codes
    ~~~~~~~~~~~~~~~~~~~~~~~~~^^
  File "/Users/cto/myvenv/lib/python3.13/site-packages/requests/models.py", line 1024, in raise_for_status
    raise HTTPError(http_error_msg, response=self)
requests.exceptions.HTTPError: 500 Server Error: Internal Server Error for url: http://localhost:9001/webhook-receiver

[6b4318bf-3e4d-4167-ac3f-fbeb98012eb3] Error sending webhook for reference_id=test-2025-08-08T16:19:40.498071+00:00: 500 Server Error: Internal Server Error for url: http://localhost:9001/webhook-receiver
[6b4318bf-3e4d-4167-ac3f-fbeb98012eb3] Stack trace: Traceback (most recent call last):
  File "/Users/cto/Desktop/projects/yolo/api.py", line 852, in send_webhook_notification
    raise e
  File "/Users/cto/Desktop/projects/yolo/api.py", line 843, in send_webhook_notification
    response.raise_for_status()  # Raise exception for 5XX status codes
    ~~~~~~~~~~~~~~~~~~~~~~~~~^^
  File "/Users/cto/myvenv/lib/python3.13/site-packages/requests/models.py", line 1024, in raise_for_status
    raise HTTPError(http_error_msg, response=self)
requests.exceptions.HTTPError: 500 Server Error: Internal Server Error for url: http://localhost:9001/webhook-receiver

[f64dea1d-bd29-4bcb-9865-0a2fabee7ef6] Error sending webhook for reference_id=test-2025-08-08T16:24:01.756456+00:00: 500 Server Error: Internal Server Error for url: http://localhost:9001/webhook-receiver
[f64dea1d-bd29-4bcb-9865-0a2fabee7ef6] Stack trace: Traceback (most recent call last):
  File "/Users/cto/Desktop/projects/yolo/api.py", line 852, in send_webhook_notification
    raise e
  File "/Users/cto/Desktop/projects/yolo/api.py", line 843, in send_webhook_notification
    response.raise_for_status()  # Raise exception for 5XX status codes
    ~~~~~~~~~~~~~~~~~~~~~~~~~^^
  File "/Users/cto/myvenv/lib/python3.13/site-packages/requests/models.py", line 1024, in raise_for_status
    raise HTTPError(http_error_msg, response=self)
requests.exceptions.HTTPError: 500 Server Error: Internal Server Error for url: http://localhost:9001/webhook-receiver

[f64dea1d-bd29-4bcb-9865-0a2fabee7ef6] Error sending webhook for reference_id=test-2025-08-08T16:24:01.756456+00:00: 500 Server Error: Internal Server Error for url: http://localhost:9001/webhook-receiver
[f64dea1d-bd29-4bcb-9865-0a2fabee7ef6] Stack trace: Traceback (most recent call last):
  File "/Users/cto/Desktop/projects/yolo/api.py", line 852, in send_webhook_notification
    raise e
  File "/Users/cto/Desktop/projects/yolo/api.py", line 843, in send_webhook_notification
    response.raise_for_status()  # Raise exception for 5XX status codes
    ~~~~~~~~~~~~~~~~~~~~~~~~~^^
  File "/Users/cto/myvenv/lib/python3.13/site-packages/requests/models.py", line 1024, in raise_for_status
    raise HTTPError(http_error_msg, response=self)
requests.exceptions.HTTPError: 500 Server Error: Internal Server Error for url: http://localhost:9001/webhook-receiver

[6b4318bf-3e4d-4167-ac3f-fbeb98012eb3] Error sending webhook for reference_id=test-2025-08-08T16:19:40.498071+00:00: 500 Server Error: Internal Server Error for url: http://localhost:9001/webhook-receiver
[6b4318bf-3e4d-4167-ac3f-fbeb98012eb3] Stack trace: Traceback (most recent call last):
  File "/Users/cto/Desktop/projects/yolo/api.py", line 852, in send_webhook_notification
    raise e
  File "/Users/cto/Desktop/projects/yolo/api.py", line 843, in send_webhook_notification
    response.raise_for_status()  # Raise exception for 5XX status codes
    ~~~~~~~~~~~~~~~~~~~~~~~~~^^
  File "/Users/cto/myvenv/lib/python3.13/site-packages/requests/models.py", line 1024, in raise_for_status
    raise HTTPError(http_error_msg, response=self)
requests.exceptions.HTTPError: 500 Server Error: Internal Server Error for url: http://localhost:9001/webhook-receiver

[f64dea1d-bd29-4bcb-9865-0a2fabee7ef6] Error sending webhook for reference_id=test-2025-08-08T16:24:01.756456+00:00: 500 Server Error: Internal Server Error for url: http://localhost:9001/webhook-receiver
[f64dea1d-bd29-4bcb-9865-0a2fabee7ef6] Stack trace: Traceback (most recent call last):
  File "/Users/cto/Desktop/projects/yolo/api.py", line 852, in send_webhook_notification
    raise e
  File "/Users/cto/Desktop/projects/yolo/api.py", line 843, in send_webhook_notification
    response.raise_for_status()  # Raise exception for 5XX status codes
    ~~~~~~~~~~~~~~~~~~~~~~~~~^^
  File "/Users/cto/myvenv/lib/python3.13/site-packages/requests/models.py", line 1024, in raise_for_status
    raise HTTPError(http_error_msg, response=self)
requests.exceptions.HTTPError: 500 Server Error: Internal Server Error for url: http://localhost:9001/webhook-receiver

[57a15bc8-fef9-4043-af24-a31b28c74568] Error sending webhook for reference_id=test-2025-08-08T16:44:56.852527+00:00: 500 Server Error: Internal Server Error for url: http://localhost:9001/webhook-receiver
[57a15bc8-fef9-4043-af24-a31b28c74568] Stack trace: Traceback (most recent call last):
  File "/Users/cto/Desktop/projects/yolo/api.py", line 917, in send_webhook_notification
    raise e
  File "/Users/cto/Desktop/projects/yolo/api.py", line 908, in send_webhook_notification
    response.raise_for_status()  # Raise exception for 5XX status codes
    ~~~~~~~~~~~~~~~~~~~~~~~~~^^
  File "/Users/cto/myvenv/lib/python3.13/site-packages/requests/models.py", line 1024, in raise_for_status
    raise HTTPError(http_error_msg, response=self)
requests.exceptions.HTTPError: 500 Server Error: Internal Server Error for url: http://localhost:9001/webhook-receiver

[57a15bc8-fef9-4043-af24-a31b28c74568] Error sending webhook for reference_id=test-2025-08-08T16:44:56.852527+00:00: 500 Server Error: Internal Server Error for url: http://localhost:9001/webhook-receiver
[57a15bc8-fef9-4043-af24-a31b28c74568] Stack trace: Traceback (most recent call last):
  File "/Users/cto/Desktop/projects/yolo/api.py", line 917, in send_webhook_notification
    raise e
  File "/Users/cto/Desktop/projects/yolo/api.py", line 908, in send_webhook_notification
    response.raise_for_status()  # Raise exception for 5XX status codes
    ~~~~~~~~~~~~~~~~~~~~~~~~~^^
  File "/Users/cto/myvenv/lib/python3.13/site-packages/requests/models.py", line 1024, in raise_for_status
    raise HTTPError(http_error_msg, response=self)
requests.exceptions.HTTPError: 500 Server Error: Internal Server Error for url: http://localhost:9001/webhook-receiver

[57a15bc8-fef9-4043-af24-a31b28c74568] Error sending webhook for reference_id=test-2025-08-08T16:44:56.852527+00:00: 500 Server Error: Internal Server Error for url: http://localhost:9001/webhook-receiver
[57a15bc8-fef9-4043-af24-a31b28c74568] Stack trace: Traceback (most recent call last):
  File "/Users/cto/Desktop/projects/yolo/api.py", line 917, in send_webhook_notification
    raise e
  File "/Users/cto/Desktop/projects/yolo/api.py", line 908, in send_webhook_notification
    response.raise_for_status()  # Raise exception for 5XX status codes
    ~~~~~~~~~~~~~~~~~~~~~~~~~^^
  File "/Users/cto/myvenv/lib/python3.13/site-packages/requests/models.py", line 1024, in raise_for_status
    raise HTTPError(http_error_msg, response=self)
requests.exceptions.HTTPError: 500 Server Error: Internal Server Error for url: http://localhost:9001/webhook-receiver

[57a15bc8-fef9-4043-af24-a31b28c74568] Error sending webhook for reference_id=test-2025-08-08T16:44:56.852527+00:00: 500 Server Error: Internal Server Error for url: http://localhost:9001/webhook-receiver
[57a15bc8-fef9-4043-af24-a31b28c74568] Stack trace: Traceback (most recent call last):
  File "/Users/cto/Desktop/projects/yolo/api.py", line 917, in send_webhook_notification
    raise e
  File "/Users/cto/Desktop/projects/yolo/api.py", line 908, in send_webhook_notification
    response.raise_for_status()  # Raise exception for 5XX status codes
    ~~~~~~~~~~~~~~~~~~~~~~~~~^^
  File "/Users/cto/myvenv/lib/python3.13/site-packages/requests/models.py", line 1024, in raise_for_status
    raise HTTPError(http_error_msg, response=self)
requests.exceptions.HTTPError: 500 Server Error: Internal Server Error for url: http://localhost:9001/webhook-receiver

[06f3e326-c679-4ce9-b3b9-7d653c4d1c0c] Error sending webhook for reference_id=test-2025-08-08T16:54:07.667260+00:00: 500 Server Error: Internal Server Error for url: http://localhost:9001/webhook-receiver
[06f3e326-c679-4ce9-b3b9-7d653c4d1c0c] Stack trace: Traceback (most recent call last):
  File "/Users/cto/Desktop/projects/yolo/api.py", line 917, in send_webhook_notification
    "reference_id": reference_id,
    
  File "/Users/cto/Desktop/projects/yolo/api.py", line 908, in send_webhook_notification
    "error_type": "permanent_client_error",
    ^^^^^^^^^^^^^^^
  File "/Users/cto/myvenv/lib/python3.13/site-packages/requests/models.py", line 1024, in raise_for_status
    raise HTTPError(http_error_msg, response=self)
requests.exceptions.HTTPError: 500 Server Error: Internal Server Error for url: http://localhost:9001/webhook-receiver

[06f3e326-c679-4ce9-b3b9-7d653c4d1c0c] Error sending webhook for reference_id=test-2025-08-08T16:54:07.667260+00:00: 500 Server Error: Internal Server Error for url: http://localhost:9001/webhook-receiver
[06f3e326-c679-4ce9-b3b9-7d653c4d1c0c] Stack trace: Traceback (most recent call last):
  File "/Users/cto/Desktop/projects/yolo/api.py", line 917, in send_webhook_notification
    "reference_id": reference_id,
    
  File "/Users/cto/Desktop/projects/yolo/api.py", line 908, in send_webhook_notification
    "error_type": "permanent_client_error",
    ^^^^^^^^^^^^^^^
  File "/Users/cto/myvenv/lib/python3.13/site-packages/requests/models.py", line 1024, in raise_for_status
    raise HTTPError(http_error_msg, response=self)
requests.exceptions.HTTPError: 500 Server Error: Internal Server Error for url: http://localhost:9001/webhook-receiver

[06f3e326-c679-4ce9-b3b9-7d653c4d1c0c] Error sending webhook for reference_id=test-2025-08-08T16:54:07.667260+00:00: 500 Server Error: Internal Server Error for url: http://localhost:9001/webhook-receiver
[06f3e326-c679-4ce9-b3b9-7d653c4d1c0c] Stack trace: Traceback (most recent call last):
  File "/Users/cto/Desktop/projects/yolo/api.py", line 917, in send_webhook_notification
    "reference_id": reference_id,
    
  File "/Users/cto/Desktop/projects/yolo/api.py", line 908, in send_webhook_notification
    "error_type": "permanent_client_error",
    ^^^^^^^^^^^^^^^
  File "/Users/cto/myvenv/lib/python3.13/site-packages/requests/models.py", line 1024, in raise_for_status
    raise HTTPError(http_error_msg, response=self)
requests.exceptions.HTTPError: 500 Server Error: Internal Server Error for url: http://localhost:9001/webhook-receiver

[06f3e326-c679-4ce9-b3b9-7d653c4d1c0c] Error sending webhook for reference_id=test-2025-08-08T16:54:07.667260+00:00: 500 Server Error: Internal Server Error for url: http://localhost:9001/webhook-receiver
[06f3e326-c679-4ce9-b3b9-7d653c4d1c0c] Stack trace: Traceback (most recent call last):
  File "/Users/cto/Desktop/projects/yolo/api.py", line 917, in send_webhook_notification
    "reference_id": reference_id,
    
  File "/Users/cto/Desktop/projects/yolo/api.py", line 908, in send_webhook_notification
    "error_type": "permanent_client_error",
    ^^^^^^^^^^^^^^^
  File "/Users/cto/myvenv/lib/python3.13/site-packages/requests/models.py", line 1024, in raise_for_status
    raise HTTPError(http_error_msg, response=self)
requests.exceptions.HTTPError: 500 Server Error: Internal Server Error for url: http://localhost:9001/webhook-receiver

[2bed88bf-1d5b-4d26-ac61-dabbd75dd993] Error sending webhook for reference_id=test-2025-08-08T17:04:24.274458+00:00: Client error: 405
[2bed88bf-1d5b-4d26-ac61-dabbd75dd993] Stack trace: Traceback (most recent call last):
  File "/Users/cto/Desktop/projects/yolo/api.py", line 917, in send_webhook_notification
    "status": "failed",
    
  File "/Users/cto/Desktop/projects/yolo/api.py", line 905, in send_webhook_notification
    headers=headers,
        ^^^^^^^^^^^^
requests.exceptions.HTTPError: Client error: 405

[f64dea1d-bd29-4bcb-9865-0a2fabee7ef6] Error sending webhook for reference_id=test-2025-08-08T16:24:01.756456+00:00: 500 Server Error: Internal Server Error for url: http://localhost:9001/webhook-receiver
[f64dea1d-bd29-4bcb-9865-0a2fabee7ef6] Stack trace: Traceback (most recent call last):
  File "/Users/cto/Desktop/projects/yolo/api.py", line 917, in send_webhook_notification
    error_msg = f"Webhook connection error for reference_id={reference_id}: {str(e)}"
        ^^^^^^^
  File "/Users/cto/Desktop/projects/yolo/api.py", line 908, in send_webhook_notification
    # No need for explicit duration tracking - the context manager handles it
  File "/Users/cto/myvenv/lib/python3.13/site-packages/requests/models.py", line 1024, in raise_for_status
    raise HTTPError(http_error_msg, response=self)
requests.exceptions.HTTPError: 500 Server Error: Internal Server Error for url: http://localhost:9001/webhook-receiver

[901b9369-ebad-4827-9acb-0c6a0da351d0] Error sending webhook for reference_id=test-2025-08-08T17:26:10.186827+00:00: Client error: 405
[901b9369-ebad-4827-9acb-0c6a0da351d0] Stack trace: Traceback (most recent call last):
  File "/Users/cto/Desktop/projects/yolo/api.py", line 917, in send_webhook_notification
    error_msg = f"Webhook connection error for reference_id={reference_id}: {str(e)}"
        ^^^^^^^
  File "/Users/cto/Desktop/projects/yolo/api.py", line 905, in send_webhook_notification
    "updated_at": get_iso_timestamp()
            ^^^^^^^^^^^^^^^^^^^^^^^^^
requests.exceptions.HTTPError: Client error: 405

[3f0af299-8f0c-49e1-b6db-245184afaef3] Error sending webhook for reference_id=test-2025-08-08T17:28:17.686389+00:00: 500 Server Error: Internal Server Error for url: http://localhost:9001/webhook-receiver
[3f0af299-8f0c-49e1-b6db-245184afaef3] Stack trace: Traceback (most recent call last):
  File "/Users/cto/Desktop/projects/yolo/api.py", line 917, in send_webhook_notification
    error_msg = f"Webhook connection error for reference_id={reference_id}: {str(e)}"
        ^^^^^^^
  File "/Users/cto/Desktop/projects/yolo/api.py", line 908, in send_webhook_notification
    # No need for explicit duration tracking - the context manager handles it
  File "/Users/cto/myvenv/lib/python3.13/site-packages/requests/models.py", line 1024, in raise_for_status
    raise HTTPError(http_error_msg, response=self)
requests.exceptions.HTTPError: 500 Server Error: Internal Server Error for url: http://localhost:9001/webhook-receiver

[3f0af299-8f0c-49e1-b6db-245184afaef3] Error sending webhook for reference_id=test-2025-08-08T17:28:17.686389+00:00: 500 Server Error: Internal Server Error for url: http://localhost:9001/webhook-receiver
[3f0af299-8f0c-49e1-b6db-245184afaef3] Stack trace: Traceback (most recent call last):
  File "/Users/cto/Desktop/projects/yolo/api.py", line 917, in send_webhook_notification
    error_msg = f"Webhook connection error for reference_id={reference_id}: {str(e)}"
        ^^^^^^^
  File "/Users/cto/Desktop/projects/yolo/api.py", line 908, in send_webhook_notification
    # No need for explicit duration tracking - the context manager handles it
  File "/Users/cto/myvenv/lib/python3.13/site-packages/requests/models.py", line 1024, in raise_for_status
    raise HTTPError(http_error_msg, response=self)
requests.exceptions.HTTPError: 500 Server Error: Internal Server Error for url: http://localhost:9001/webhook-receiver

[ce22842b-98d9-4003-912f-5cd31b35a4b7] Error sending webhook for reference_id=test-2025-08-08T17:30:17.909267+00:00: 500 Server Error: Internal Server Error for url: http://localhost:9001/webhook-receiver
[ce22842b-98d9-4003-912f-5cd31b35a4b7] Stack trace: Traceback (most recent call last):
  File "/Users/cto/Desktop/projects/yolo/api.py", line 917, in send_webhook_notification
  File "/Users/cto/Desktop/projects/yolo/api.py", line 908, in send_webhook_notification
    except requests.exceptions.HTTPError as e:
        ^^^^^^^^^^^^^^^^^^^^^^^^^^^
  File "/Users/cto/myvenv/lib/python3.13/site-packages/requests/models.py", line 1024, in raise_for_status
    raise HTTPError(http_error_msg, response=self)
requests.exceptions.HTTPError: 500 Server Error: Internal Server Error for url: http://localhost:9001/webhook-receiver

[3f0af299-8f0c-49e1-b6db-245184afaef3] Error sending webhook for reference_id=test-2025-08-08T17:28:17.686389+00:00: 500 Server Error: Internal Server Error for url: http://localhost:9001/webhook-receiver
[3f0af299-8f0c-49e1-b6db-245184afaef3] Stack trace: Traceback (most recent call last):
  File "/Users/cto/Desktop/projects/yolo/api.py", line 917, in send_webhook_notification
  File "/Users/cto/Desktop/projects/yolo/api.py", line 908, in send_webhook_notification
    except requests.exceptions.HTTPError as e:
        ^^^^^^^^^^^^^^^^^^^^^^^^^^^
  File "/Users/cto/myvenv/lib/python3.13/site-packages/requests/models.py", line 1024, in raise_for_status
    raise HTTPError(http_error_msg, response=self)
requests.exceptions.HTTPError: 500 Server Error: Internal Server Error for url: http://localhost:9001/webhook-receiver

[ce22842b-98d9-4003-912f-5cd31b35a4b7] Error sending webhook for reference_id=test-2025-08-08T17:30:17.909267+00:00: 500 Server Error: Internal Server Error for url: http://localhost:9001/webhook-receiver
[ce22842b-98d9-4003-912f-5cd31b35a4b7] Stack trace: Traceback (most recent call last):
  File "/Users/cto/Desktop/projects/yolo/api.py", line 917, in send_webhook_notification
  File "/Users/cto/Desktop/projects/yolo/api.py", line 908, in send_webhook_notification
    except requests.exceptions.HTTPError as e:
        ^^^^^^^^^^^^^^^^^^^^^^^^^^^
  File "/Users/cto/myvenv/lib/python3.13/site-packages/requests/models.py", line 1024, in raise_for_status
    raise HTTPError(http_error_msg, response=self)
requests.exceptions.HTTPError: 500 Server Error: Internal Server Error for url: http://localhost:9001/webhook-receiver

[ce22842b-98d9-4003-912f-5cd31b35a4b7] Error sending webhook for reference_id=test-2025-08-08T17:30:17.909267+00:00: 500 Server Error: Internal Server Error for url: http://localhost:9001/webhook-receiver
[ce22842b-98d9-4003-912f-5cd31b35a4b7] Stack trace: Traceback (most recent call last):
  File "/Users/cto/Desktop/projects/yolo/api.py", line 917, in send_webhook_notification
  File "/Users/cto/Desktop/projects/yolo/api.py", line 908, in send_webhook_notification
    except requests.exceptions.HTTPError as e:
        ^^^^^^^^^^^^^^^^^^^^^^^^^^^
  File "/Users/cto/myvenv/lib/python3.13/site-packages/requests/models.py", line 1024, in raise_for_status
    raise HTTPError(http_error_msg, response=self)
requests.exceptions.HTTPError: 500 Server Error: Internal Server Error for url: http://localhost:9001/webhook-receiver

[8bab2432-f696-46be-9008-2fd0ed3ec3a6] Error sending webhook for reference_id=test-2025-08-08T17:32:25.050106+00:00: 500 Server Error: Internal Server Error for url: http://localhost:9001/webhook-receiver
[8bab2432-f696-46be-9008-2fd0ed3ec3a6] Stack trace: Traceback (most recent call last):
  File "/Users/cto/Desktop/projects/yolo/api.py", line 917, in send_webhook_notification
    "response_code": response.status_code,
    
  File "/Users/cto/Desktop/projects/yolo/api.py", line 908, in send_webhook_notification
    # Handle 4xx responses differently - only retry once for client errors
  File "/Users/cto/myvenv/lib/python3.13/site-packages/requests/models.py", line 1024, in raise_for_status
    raise HTTPError(http_error_msg, response=self)
requests.exceptions.HTTPError: 500 Server Error: Internal Server Error for url: http://localhost:9001/webhook-receiver

[3f0af299-8f0c-49e1-b6db-245184afaef3] Error sending webhook for reference_id=test-2025-08-08T17:28:17.686389+00:00: 500 Server Error: Internal Server Error for url: http://localhost:9001/webhook-receiver
[3f0af299-8f0c-49e1-b6db-245184afaef3] Stack trace: Traceback (most recent call last):
  File "/Users/cto/Desktop/projects/yolo/api.py", line 917, in send_webhook_notification
    "response_code": response.status_code,
    
  File "/Users/cto/Desktop/projects/yolo/api.py", line 908, in send_webhook_notification
    # Handle 4xx responses differently - only retry once for client errors
  File "/Users/cto/myvenv/lib/python3.13/site-packages/requests/models.py", line 1024, in raise_for_status
    raise HTTPError(http_error_msg, response=self)
requests.exceptions.HTTPError: 500 Server Error: Internal Server Error for url: http://localhost:9001/webhook-receiver

[8bab2432-f696-46be-9008-2fd0ed3ec3a6] Error sending webhook for reference_id=test-2025-08-08T17:32:25.050106+00:00: 500 Server Error: Internal Server Error for url: http://localhost:9001/webhook-receiver
[8bab2432-f696-46be-9008-2fd0ed3ec3a6] Stack trace: Traceback (most recent call last):
  File "/Users/cto/Desktop/projects/yolo/api.py", line 917, in send_webhook_notification
    "response_code": response.status_code,
    
  File "/Users/cto/Desktop/projects/yolo/api.py", line 908, in send_webhook_notification
    # Handle 4xx responses differently - only retry once for client errors
  File "/Users/cto/myvenv/lib/python3.13/site-packages/requests/models.py", line 1024, in raise_for_status
    raise HTTPError(http_error_msg, response=self)
requests.exceptions.HTTPError: 500 Server Error: Internal Server Error for url: http://localhost:9001/webhook-receiver

[d6863b2d-c54f-4068-9eba-696c1f48b262] Error sending webhook for reference_id=test-2025-08-08T17:33:39.847100+00:00: 500 Server Error: Internal Server Error for url: http://localhost:9001/webhook-receiver
[d6863b2d-c54f-4068-9eba-696c1f48b262] Stack trace: Traceback (most recent call last):
  File "/Users/cto/Desktop/projects/yolo/api.py", line 947, in send_webhook_notification
    raise e
  File "/Users/cto/Desktop/projects/yolo/api.py", line 938, in send_webhook_notification
    response.raise_for_status()  # Raise exception for 5XX status codes
    ~~~~~~~~~~~~~~~~~~~~~~~~~^^
  File "/Users/cto/myvenv/lib/python3.13/site-packages/requests/models.py", line 1024, in raise_for_status
    raise HTTPError(http_error_msg, response=self)
requests.exceptions.HTTPError: 500 Server Error: Internal Server Error for url: http://localhost:9001/webhook-receiver

[8bab2432-f696-46be-9008-2fd0ed3ec3a6] Error sending webhook for reference_id=test-2025-08-08T17:32:25.050106+00:00: 500 Server Error: Internal Server Error for url: http://localhost:9001/webhook-receiver
[8bab2432-f696-46be-9008-2fd0ed3ec3a6] Stack trace: Traceback (most recent call last):
  File "/Users/cto/Desktop/projects/yolo/api.py", line 947, in send_webhook_notification
    raise e
  File "/Users/cto/Desktop/projects/yolo/api.py", line 938, in send_webhook_notification
    response.raise_for_status()  # Raise exception for 5XX status codes
    ~~~~~~~~~~~~~~~~~~~~~~~~~^^
  File "/Users/cto/myvenv/lib/python3.13/site-packages/requests/models.py", line 1024, in raise_for_status
    raise HTTPError(http_error_msg, response=self)
requests.exceptions.HTTPError: 500 Server Error: Internal Server Error for url: http://localhost:9001/webhook-receiver

[d6863b2d-c54f-4068-9eba-696c1f48b262] Error sending webhook for reference_id=test-2025-08-08T17:33:39.847100+00:00: 500 Server Error: Internal Server Error for url: http://localhost:9001/webhook-receiver
[d6863b2d-c54f-4068-9eba-696c1f48b262] Stack trace: Traceback (most recent call last):
  File "/Users/cto/Desktop/projects/yolo/api.py", line 947, in send_webhook_notification
    raise e
  File "/Users/cto/Desktop/projects/yolo/api.py", line 938, in send_webhook_notification
    response.raise_for_status()  # Raise exception for 5XX status codes
    ~~~~~~~~~~~~~~~~~~~~~~~~~^^
  File "/Users/cto/myvenv/lib/python3.13/site-packages/requests/models.py", line 1024, in raise_for_status
    raise HTTPError(http_error_msg, response=self)
requests.exceptions.HTTPError: 500 Server Error: Internal Server Error for url: http://localhost:9001/webhook-receiver

[ce22842b-98d9-4003-912f-5cd31b35a4b7] Error sending webhook for reference_id=test-2025-08-08T17:30:17.909267+00:00: 500 Server Error: Internal Server Error for url: http://localhost:9001/webhook-receiver
[ce22842b-98d9-4003-912f-5cd31b35a4b7] Stack trace: Traceback (most recent call last):
  File "/Users/cto/Desktop/projects/yolo/api.py", line 947, in send_webhook_notification
    raise e
  File "/Users/cto/Desktop/projects/yolo/api.py", line 938, in send_webhook_notification
    response.raise_for_status()  # Raise exception for 5XX status codes
    ~~~~~~~~~~~~~~~~~~~~~~~~~^^
  File "/Users/cto/myvenv/lib/python3.13/site-packages/requests/models.py", line 1024, in raise_for_status
    raise HTTPError(http_error_msg, response=self)
requests.exceptions.HTTPError: 500 Server Error: Internal Server Error for url: http://localhost:9001/webhook-receiver

[d6863b2d-c54f-4068-9eba-696c1f48b262] Error sending webhook for reference_id=test-2025-08-08T17:33:39.847100+00:00: 500 Server Error: Internal Server Error for url: http://localhost:9001/webhook-receiver
[d6863b2d-c54f-4068-9eba-696c1f48b262] Stack trace: Traceback (most recent call last):
  File "/Users/cto/Desktop/projects/yolo/api.py", line 947, in send_webhook_notification
    raise e
  File "/Users/cto/Desktop/projects/yolo/api.py", line 938, in send_webhook_notification
    response.raise_for_status()  # Raise exception for 5XX status codes
    ~~~~~~~~~~~~~~~~~~~~~~~~~^^
  File "/Users/cto/myvenv/lib/python3.13/site-packages/requests/models.py", line 1024, in raise_for_status
    raise HTTPError(http_error_msg, response=self)
requests.exceptions.HTTPError: 500 Server Error: Internal Server Error for url: http://localhost:9001/webhook-receiver

[8bab2432-f696-46be-9008-2fd0ed3ec3a6] Error sending webhook for reference_id=test-2025-08-08T17:32:25.050106+00:00: 500 Server Error: Internal Server Error for url: http://localhost:9001/webhook-receiver
[8bab2432-f696-46be-9008-2fd0ed3ec3a6] Stack trace: Traceback (most recent call last):
  File "/Users/cto/Desktop/projects/yolo/api.py", line 947, in send_webhook_notification
    raise e
  File "/Users/cto/Desktop/projects/yolo/api.py", line 938, in send_webhook_notification
    response.raise_for_status()  # Raise exception for 5XX status codes
    ~~~~~~~~~~~~~~~~~~~~~~~~~^^
  File "/Users/cto/myvenv/lib/python3.13/site-packages/requests/models.py", line 1024, in raise_for_status
    raise HTTPError(http_error_msg, response=self)
requests.exceptions.HTTPError: 500 Server Error: Internal Server Error for url: http://localhost:9001/webhook-receiver

[d6863b2d-c54f-4068-9eba-696c1f48b262] Error sending webhook for reference_id=test-2025-08-08T17:33:39.847100+00:00: 500 Server Error: Internal Server Error for url: http://localhost:9001/webhook-receiver
[d6863b2d-c54f-4068-9eba-696c1f48b262] Stack trace: Traceback (most recent call last):
  File "/Users/cto/Desktop/projects/yolo/api.py", line 947, in send_webhook_notification
    raise e
  File "/Users/cto/Desktop/projects/yolo/api.py", line 938, in send_webhook_notification
    response.raise_for_status()  # Raise exception for 5XX status codes
    ~~~~~~~~~~~~~~~~~~~~~~~~~^^
  File "/Users/cto/myvenv/lib/python3.13/site-packages/requests/models.py", line 1024, in raise_for_status
    raise HTTPError(http_error_msg, response=self)
requests.exceptions.HTTPError: 500 Server Error: Internal Server Error for url: http://localhost:9001/webhook-receiver

[5bc5df08-13c9-4954-b9dd-721c0afede62] Error sending webhook for reference_id=test-2025-08-08T17:42:38.772446+00:00: Client error: 405
[5bc5df08-13c9-4954-b9dd-721c0afede62] Stack trace: Traceback (most recent call last):
  File "/Users/cto/Desktop/projects/yolo/api.py", line 987, in send_webhook_notification
    raise e
  File "/Users/cto/Desktop/projects/yolo/api.py", line 975, in send_webhook_notification
    raise requests.exceptions.HTTPError(f"Client error: {response.status_code}")
requests.exceptions.HTTPError: Client error: 405

[3b68d66f-170e-4eda-8d40-299e7f1c03c2] Error sending webhook for reference_id=test-2025-08-08T17:43:08.244869+00:00: 500 Server Error: Internal Server Error for url: http://localhost:9001/webhook
[3b68d66f-170e-4eda-8d40-299e7f1c03c2] Stack trace: Traceback (most recent call last):
  File "/Users/cto/Desktop/projects/yolo/api.py", line 987, in send_webhook_notification
    raise e
  File "/Users/cto/Desktop/projects/yolo/api.py", line 978, in send_webhook_notification
    response.raise_for_status()  # Raise exception for 5XX status codes
    ~~~~~~~~~~~~~~~~~~~~~~~~~^^
  File "/Users/cto/myvenv/lib/python3.13/site-packages/requests/models.py", line 1024, in raise_for_status
    raise HTTPError(http_error_msg, response=self)
requests.exceptions.HTTPError: 500 Server Error: Internal Server Error for url: http://localhost:9001/webhook

[3b68d66f-170e-4eda-8d40-299e7f1c03c2] Error sending webhook for reference_id=test-2025-08-08T17:43:08.244869+00:00: 500 Server Error: Internal Server Error for url: http://localhost:9001/webhook
[3b68d66f-170e-4eda-8d40-299e7f1c03c2] Stack trace: Traceback (most recent call last):
  File "/Users/cto/Desktop/projects/yolo/api.py", line 987, in send_webhook_notification
    raise e
  File "/Users/cto/Desktop/projects/yolo/api.py", line 978, in send_webhook_notification
    response.raise_for_status()  # Raise exception for 5XX status codes
    ~~~~~~~~~~~~~~~~~~~~~~~~~^^
  File "/Users/cto/myvenv/lib/python3.13/site-packages/requests/models.py", line 1024, in raise_for_status
    raise HTTPError(http_error_msg, response=self)
requests.exceptions.HTTPError: 500 Server Error: Internal Server Error for url: http://localhost:9001/webhook

[3b68d66f-170e-4eda-8d40-299e7f1c03c2] Error sending webhook for reference_id=test-2025-08-08T17:43:08.244869+00:00: 500 Server Error: Internal Server Error for url: http://localhost:9001/webhook
[3b68d66f-170e-4eda-8d40-299e7f1c03c2] Stack trace: Traceback (most recent call last):
  File "/Users/cto/Desktop/projects/yolo/api.py", line 987, in send_webhook_notification
    raise e
  File "/Users/cto/Desktop/projects/yolo/api.py", line 978, in send_webhook_notification
    response.raise_for_status()  # Raise exception for 5XX status codes
    ~~~~~~~~~~~~~~~~~~~~~~~~~^^
  File "/Users/cto/myvenv/lib/python3.13/site-packages/requests/models.py", line 1024, in raise_for_status
    raise HTTPError(http_error_msg, response=self)
requests.exceptions.HTTPError: 500 Server Error: Internal Server Error for url: http://localhost:9001/webhook

[3b68d66f-170e-4eda-8d40-299e7f1c03c2] Error sending webhook for reference_id=test-2025-08-08T17:43:08.244869+00:00: 500 Server Error: Internal Server Error for url: http://localhost:9001/webhook
[3b68d66f-170e-4eda-8d40-299e7f1c03c2] Stack trace: Traceback (most recent call last):
  File "/Users/cto/Desktop/projects/yolo/api.py", line 987, in send_webhook_notification
    raise e
  File "/Users/cto/Desktop/projects/yolo/api.py", line 978, in send_webhook_notification
    response.raise_for_status()  # Raise exception for 5XX status codes
    ~~~~~~~~~~~~~~~~~~~~~~~~~^^
  File "/Users/cto/myvenv/lib/python3.13/site-packages/requests/models.py", line 1024, in raise_for_status
    raise HTTPError(http_error_msg, response=self)
requests.exceptions.HTTPError: 500 Server Error: Internal Server Error for url: http://localhost:9001/webhook

[b1843e7d-6546-43db-bacf-2e8f63e82de5] Error sending webhook for reference_id=test-2025-08-08T17:51:08.396742+00:00: 500 Server Error: Internal Server Error for url: http://localhost:9001/webhook
[b1843e7d-6546-43db-bacf-2e8f63e82de5] Stack trace: Traceback (most recent call last):
  File "/Users/cto/Desktop/projects/yolo/api.py", line 988, in send_webhook_notification
    raise e
  File "/Users/cto/Desktop/projects/yolo/api.py", line 979, in send_webhook_notification
    response.raise_for_status()  # Raise exception for 5XX status codes
    ~~~~~~~~~~~~~~~~~~~~~~~~~^^
  File "/Users/cto/myvenv/lib/python3.13/site-packages/requests/models.py", line 1024, in raise_for_status
    raise HTTPError(http_error_msg, response=self)
requests.exceptions.HTTPError: 500 Server Error: Internal Server Error for url: http://localhost:9001/webhook

[b1843e7d-6546-43db-bacf-2e8f63e82de5] Error sending webhook for reference_id=test-2025-08-08T17:51:08.396742+00:00: 500 Server Error: Internal Server Error for url: http://localhost:9001/webhook
[b1843e7d-6546-43db-bacf-2e8f63e82de5] Stack trace: Traceback (most recent call last):
  File "/Users/cto/Desktop/projects/yolo/api.py", line 988, in send_webhook_notification
    raise e
  File "/Users/cto/Desktop/projects/yolo/api.py", line 979, in send_webhook_notification
    response.raise_for_status()  # Raise exception for 5XX status codes
    ~~~~~~~~~~~~~~~~~~~~~~~~~^^
  File "/Users/cto/myvenv/lib/python3.13/site-packages/requests/models.py", line 1024, in raise_for_status
    raise HTTPError(http_error_msg, response=self)
requests.exceptions.HTTPError: 500 Server Error: Internal Server Error for url: http://localhost:9001/webhook

[b1843e7d-6546-43db-bacf-2e8f63e82de5] Error sending webhook for reference_id=test-2025-08-08T17:51:08.396742+00:00: 500 Server Error: Internal Server Error for url: http://localhost:9001/webhook
[b1843e7d-6546-43db-bacf-2e8f63e82de5] Stack trace: Traceback (most recent call last):
  File "/Users/cto/Desktop/projects/yolo/api.py", line 988, in send_webhook_notification
    raise e
  File "/Users/cto/Desktop/projects/yolo/api.py", line 979, in send_webhook_notification
    response.raise_for_status()  # Raise exception for 5XX status codes
    ~~~~~~~~~~~~~~~~~~~~~~~~~^^
  File "/Users/cto/myvenv/lib/python3.13/site-packages/requests/models.py", line 1024, in raise_for_status
    raise HTTPError(http_error_msg, response=self)
requests.exceptions.HTTPError: 500 Server Error: Internal Server Error for url: http://localhost:9001/webhook

[b1843e7d-6546-43db-bacf-2e8f63e82de5] Error sending webhook for reference_id=test-2025-08-08T17:51:08.396742+00:00: 500 Server Error: Internal Server Error for url: http://localhost:9001/webhook
[b1843e7d-6546-43db-bacf-2e8f63e82de5] Stack trace: Traceback (most recent call last):
  File "/Users/cto/Desktop/projects/yolo/api.py", line 988, in send_webhook_notification
    raise e
  File "/Users/cto/Desktop/projects/yolo/api.py", line 979, in send_webhook_notification
    response.raise_for_status()  # Raise exception for 5XX status codes
    ~~~~~~~~~~~~~~~~~~~~~~~~~^^
  File "/Users/cto/myvenv/lib/python3.13/site-packages/requests/models.py", line 1024, in raise_for_status
    raise HTTPError(http_error_msg, response=self)
requests.exceptions.HTTPError: 500 Server Error: Internal Server Error for url: http://localhost:9001/webhook

